<mujoco model="bruce">
    <compiler angle="radian" meshdir="../meshes/" />
    <size njmax="2000" nconmax="500" />
    <option solver="PGS" gravity='0 0 -9.81'/>
    
    <asset>
        <texture type='skybox' builtin='gradient' width='128' height='128' rgb1='0.4 0.6 0.8' rgb2='0 0 0'/>
        <texture name='plane' type='2d' builtin='checker' rgb1='0.2 0.2 0.2' rgb2='0.3 0.3 0.3' width='512' height='512'/>
        <material name='plane' reflectance='0.0' texture='plane' texrepeat='1 1' texuniform='true'/>
    </asset>


    <asset>
        <mesh name="base_link" file="base_link.STL" />
        <mesh name="hip_yaw_link_r" file="hip_yaw_link_r.STL" />
        <mesh name="hip_roll_link_r" file="hip_roll_link_r.STL" />
        <mesh name="hip_pitch_link_r" file="hip_pitch_link_r.STL" />
        <mesh name="knee_pitch_link_r" file="knee_pitch_link_r.STL" />
        <mesh name="ankle_pitch_link_r" file="ankle_pitch_link_r.STL" />
        <mesh name="hip_yaw_link_l" file="hip_yaw_link_l.STL" />
        <mesh name="hip_roll_link_l" file="hip_roll_link_l.STL" />
        <mesh name="hip_pitch_link_l" file="hip_pitch_link_l.STL" />
        <mesh name="knee_pitch_link_l" file="knee_pitch_link_l.STL" />
        <mesh name="ankle_pitch_link_l" file="ankle_pitch_link_l.STL" />
        <mesh name="shoulder_pitch_link_r" file="shoulder_pitch_link_r.STL" />
        <mesh name="shoulder_roll_link_r" file="shoulder_roll_link_r.STL" />
        <mesh name="elbow_pitch_link_r" file="elbow_pitch_link_r.STL" />
        <mesh name="shoulder_pitch_link_l" file="shoulder_pitch_link_l.STL" />
        <mesh name="shoulder_roll_link_l" file="shoulder_roll_link_l.STL" />
        <mesh name="elbow_pitch_link_l" file="elbow_pitch_link_l.STL" />   
    </asset>


    <worldbody>

        <light directional="true" diffuse=".8 .8 .8" pos="0 0 10" dir="0 0 -10"/>
        <camera name="track" mode="trackcom" pos="0 -13 16" xyaxes="1 0 0 0 0.707 0.707"/>
        <geom name='floor' type='plane' conaffinity='1' condim='3' contype='1' rgba="0.5 0.9 0.9 0.1" material='plane' pos='0 0 0' size='0 0 1'/>

        <!--body name="base_link" pos="0.022596 -0.00011305 0.0614005"-->
        <body name="base_link" pos="0 0 0.43">
            <freejoint name="root" />
            <inertial pos="0.022596 -0.00011305 0.0614005" quat="0.994116 -0.000933698 -0.108309 -0.00092819" mass="1.31689" diaginertia="0.0137572 0.0102363 0.00506804" />
            
            <geom type="mesh" contype="0" conaffinity="0" group="1" rgba="0.752941 0.752941 0.752941 1" mesh="base_link" />
            <geom type="mesh" rgba="0.752941 0.752941 0.752941 1" mesh="base_link"/>
            <site name="imu" type="sphere" size="0.01" pos="0 0 0"/>
            
            
            <body name="hip_yaw_link_r" pos="0.029216 -0.0758557 -0.039765" quat="0.707107 0 0 -0.707107">
                <inertial pos="2.71e-06 -0.00024824 0.00522427" quat="0.517691 0.482114 0.518083 0.480784" mass="0.637563" diaginertia="0.0016174 0.00152078 0.000485406" />
                <joint name="hip_yaw_r" pos="0 0 0" axis="0 0 1" limited="true" range="-3.14 3.14" armature='0.00182' damping='1'/>
                <geom type="mesh" rgba="0.752941 0.752941 0.752941 1" mesh="hip_yaw_link_r" />
                
            </body>

            <body name="hip_yaw_link_l" pos="0.029216 0.0758557 -0.039765" quat="0.707107 0 0 -0.707107">
                <inertial pos="0 -0.00020849 0.00528032" quat="0.518836 0.480432 0.518756 0.480506" mass="0.637386" diaginertia="0.00161868 0.00152047 0.0004852" />
                <joint name="hip_yaw_l" pos="0 0 0" axis="0 0 1" limited="true" range="-3.14 3.14" armature='0.00182' damping='1'/>
                <geom type="mesh" rgba="0.752941 0.752941 0.752941 1" mesh="hip_yaw_link_l" />
               
            </body>
    
        </body>
    </worldbody>

    <actuator>       
        
        <motor name="hip_yaw_r_motor"  joint="hip_yaw_r"  gear='9' ctrllimited='true' ctrlrange='-5 5'/>
        <motor name="hip_yaw_r_lmotor"  joint="hip_yaw_l"  gear='9' ctrllimited='true' ctrlrange='-5 5'/>


    </actuator>

    <sensor>

        <subtreecom body="base_link" name="subtreecom" />
       
        <accelerometer name="Body_Acc" site="imu" noise='1e-2' cutoff='157'/>
        <gyro name="Body_Gyro" site="imu" noise='5e-4' cutoff='34.9'/>
        <framepos name="Body_Pos" objtype="site" objname="imu"/>
        <framequat name="Body_Quat" objtype="site" objname="imu"/>
        <framelinvel name="Body_Vel" objtype="site" objname="imu"/>
        
    </sensor>
</mujoco>
